Workbook

Sheet Quarterly P&L
B1: MIDOFFICE DATA | Profit & Loss Statement | FY 2025-26 (Apr 2025 – Mar 2026)
B2: India Parent (Midoffice Data Solutions Pvt Ltd) + US Subsidiary (Midoffice Data International Inc.) | Accrual Basis | FX: ₹90/USD | COGS: 2025-09 onwards | All amounts in INR (₹)
B4: Line Item | C4: Q1 (Apr–Jun 25) | D4: Q2 (Jul–Sep 25) | E4: Q3 (Oct–Dec 25) | F4: Q4 (Jan–Mar 26) | G4: FY 2025-26 | H4: % Rev
B5: REVENUE
B6: Tech Mahindra (TechM) Billings | C6: =SUM('Monthly P&L'!C5:E5) | D6: =SUM('Monthly P&L'!F5:H5) | E6: =SUM('Monthly P&L'!I5:K5) | F6: =SUM('Monthly P&L'!L5:N5) | G6: =SUM(C6:F6) | H6: =IFERROR(G6/$G$9,0)
B7: BSM — Platform AMC + Accrual Generation Feature Enablement | C7: =SUM('Monthly P&L'!C6:E6) | D7: =SUM('Monthly P&L'!F6:H6) | E7: =SUM('Monthly P&L'!I6:K6) | F7: =SUM('Monthly P&L'!L6:N6) | G7: =SUM(C7:F7) | H7: =IFERROR(G7/$G$9,0)
B8: Fixed Deposit Interest Income | C8: =SUM('Monthly P&L'!C7:E7) | D8: =SUM('Monthly P&L'!F7:H7) | E8: =SUM('Monthly P&L'!I7:K7) | F8: =SUM('Monthly P&L'!L7:N7) | G8: =SUM(C8:F8) | H8: =IFERROR(G8/$G$9,0)
B9: TOTAL REVENUE | C9: =SUM(C6:C8) | D9: =SUM(D6:D8) | E9: =SUM(E6:E8) | F9: =SUM(F6:F8) | G9: =SUM(G6:G8) | H9: =IFERROR(G9/$G$9,0)
B11: COST OF GOODS SOLD (COGS)
B12: Delivery — India | C12: =SUM('COGS Allocation Working'!E4:G9) | D12: =SUM('COGS Allocation Working'!H4:J9) | E12: =SUM('COGS Allocation Working'!K4:M9) | F12: =SUM('COGS Allocation Working'!N4:P9) | G12: =SUM(C12:F12) | H12: =IFERROR(G12/$G$9,0)
B13: BSM Delivery Contractors | C13: =SUM('COGS Allocation Working'!E12:G12) | D13: =SUM('COGS Allocation Working'!H12:J12) | E13: =SUM('COGS Allocation Working'!K12:M12) | F13: =SUM('COGS Allocation Working'!N12:P12) | G13: =SUM(C13:F13) | H13: =IFERROR(G13/$G$9,0)
B14: Ramki — Delivery Allocation (50% COGS, Sep-Mar) | C14: =SUM('COGS Allocation Working'!E10:G10) | D14: =SUM('COGS Allocation Working'!H10:J10) | E14: =SUM('COGS Allocation Working'!K10:M10) | F14: =SUM('COGS Allocation Working'!N10:P10) | G14: =SUM(C14:F14) | H14: =IFERROR(G14/$G$9,0)
B15: Dorothea Stoll — Account & Delivery (COGS, Oct-Mar) | C15: =SUM('COGS Allocation Working'!E11:G11) | D15: =SUM('COGS Allocation Working'!H11:J11) | E15: =SUM('COGS Allocation Working'!K11:M11) | F15: =SUM('COGS Allocation Working'!N11:P11) | G15: =SUM(C15:F15) | H15: =IFERROR(G15/$G$9,0)
B16: External Delivery Vendors (Conam + Biltzentech +Altysys ) | C16: =SUM('COGS Allocation Working'!E13:G14) | D16: =SUM('COGS Allocation Working'!H13:J14) | E16: =SUM('COGS Allocation Working'!K13:M14) | F16: =SUM('COGS Allocation Working'!N13:P14) | G16: =SUM(C16:F16) | H16: =IFERROR(G16/$G$9,0)
B17: Technology Costs | C17: =25800.0*3 | D17: =25800.0*3 | E17: =25800.0*3 | F17: =25800.0*3 | G17: =SUM(C17:F17) | H17: =IFERROR(G17/$G$9,0)
B18: TOTAL COGS | C18: =SUM(C12:C17) | D18: =SUM(D12:D17) | E18: =SUM(E12:E17) | F18: =SUM(F12:F17) | G18: =SUM(G12:G17) | H18: =IFERROR(G18/$G$9,0)
B20: GROSS PROFIT | C20: =C9-C18 | D20: =D9-D18 | E20: =E9-E18 | F20: =F9-F18 | G20: =G9-G18 | H20: =IFERROR(G20/$G$9,0)
B21: Gross Margin % | C21: =IFERROR(C20/C9,0) | D21: =IFERROR(D20/D9,0) | E21: =IFERROR(E20/E9,0) | F21: =IFERROR(F20/F9,0) | G21: =IFERROR(AVERAGE(C21:F21),0)
B23: OPERATING EXPENSES
B24: Sales & Marketing (S&M)
B25: Ramki — S&M Allocation (100% Apr-Aug | 50% Sep-Mar) | C25: =SUM('Monthly P&L'!C13:E13) | D25: =SUM('Monthly P&L'!F13:H13) | E25: =SUM('Monthly P&L'!I13:K13) | F25: =SUM('Monthly P&L'!L13:N13) | G25: =SUM(C25:F25) | H25: =IFERROR(G25/$G$9,0)
B26: Advertising & Marketing | C26: =SUM('Monthly P&L'!C14:E14) | D26: =SUM('Monthly P&L'!F14:H14) | E26: =SUM('Monthly P&L'!I14:K14) | F26: =SUM('Monthly P&L'!L14:N14) | G26: =SUM(C26:F26) | H26: =IFERROR(G26/$G$9,0)
B27: Travel Expenses | C27: =SUM('Monthly P&L'!C15:E15) | D27: =SUM('Monthly P&L'!F15:H15) | E27: =SUM('Monthly P&L'!I15:K15) | F27: =SUM('Monthly P&L'!L15:N15) | G27: =SUM(C27:F27) | H27: =IFERROR(G27/$G$9,0)
B28: Meals & Entertainment | C28: =SUM('Monthly P&L'!C16:E16) | D28: =SUM('Monthly P&L'!F16:H16) | E28: =SUM('Monthly P&L'!I16:K16) | F28: =SUM('Monthly P&L'!L16:N16) | G28: =SUM(C28:F28) | H28: =IFERROR(G28/$G$9,0)
B29: Total S&M | C29: =SUM(C25:C28) | D29: =SUM(D25:D28) | E29: =SUM(E25:E28) | F29: =SUM(F25:F28) | G29: =SUM(G25:G28) | H29: =IFERROR(G29/$G$9,0)
B31: Research & Development (R&D)
B32: India Salaries — R&D & Overhead | C32: =SUM('Monthly P&L'!C19:E19) | D32: =SUM('Monthly P&L'!F19:H19) | E32: =SUM('Monthly P&L'!I19:K19) | F32: =SUM('Monthly P&L'!L19:N19) | G32: =SUM(C32:F32) | H32: =IFERROR(G32/$G$9,0)
B33: Consultant & Contractor Expense (StackPro + R&D vendors) | C33: =SUM('Monthly P&L'!C20:E20) | D33: =SUM('Monthly P&L'!F20:H20) | E33: =SUM('Monthly P&L'!I20:K20) | F33: =SUM('Monthly P&L'!L20:N20) | G33: =SUM(C33:F33) | H33: =IFERROR(G33/$G$9,0)
B34: Software Subscriptions | C34: =SUM('Monthly P&L'!C21:E21) | D34: =SUM('Monthly P&L'!F21:H21) | E34: =SUM('Monthly P&L'!I21:K21) | F34: =SUM('Monthly P&L'!L21:N21) | G34: =SUM(C34:F34) | H34: =IFERROR(G34/$G$9,0)
B35: Total R&D | C35: =SUM(C32:C34) | D35: =SUM(D32:D34) | E35: =SUM(E32:E34) | F35: =SUM(F32:F34) | G35: =SUM(G32:G34) | H35: =IFERROR(G35/$G$9,0)
B37: General & Administrative (G&A)
B38: Rent (Innov8 co-working) | C38: =SUM('Monthly P&L'!C24:E24) | D38: =SUM('Monthly P&L'!F24:H24) | E38: =SUM('Monthly P&L'!I24:K24) | F38: =SUM('Monthly P&L'!L24:N24) | G38: =SUM(C38:F38) | H38: =IFERROR(G38/$G$9,0)
B39: IT & Internet Expenses | C39: =SUM('Monthly P&L'!C25:E25) | D39: =SUM('Monthly P&L'!F25:H25) | E39: =SUM('Monthly P&L'!I25:K25) | F39: =SUM('Monthly P&L'!L25:N25) | G39: =SUM(C39:F39) | H39: =IFERROR(G39/$G$9,0)
B40: Legal Expenses | C40: =SUM('Monthly P&L'!C26:E26) | D40: =SUM('Monthly P&L'!F26:H26) | E40: =SUM('Monthly P&L'!I26:K26) | F40: =SUM('Monthly P&L'!L26:N26) | G40: =SUM(C40:F40) | H40: =IFERROR(G40/$G$9,0)
B41: Audit Fees & Non-Operating | C41: =SUM('Monthly P&L'!C27:E27) | D41: =SUM('Monthly P&L'!F27:H27) | E41: =SUM('Monthly P&L'!I27:K27) | F41: =SUM('Monthly P&L'!L27:N27) | G41: =SUM(C41:F41) | H41: =IFERROR(G41/$G$9,0)
B42: Other G&A (bank fees, merchandise, other) | C42: =SUM('Monthly P&L'!C28:E28) | D42: =SUM('Monthly P&L'!F28:H28) | E42: =SUM('Monthly P&L'!I28:K28) | F42: =SUM('Monthly P&L'!L28:N28) | G42: =SUM(C42:F42) | H42: =IFERROR(G42/$G$9,0)
B43: Total G&A | C43: =SUM(C38:C42) | D43: =SUM(D38:D42) | E43: =SUM(E38:E42) | F43: =SUM(F38:F42) | G43: =SUM(G38:G42) | H43: =IFERROR(G43/$G$9,0)
B45: TOTAL OPERATING EXPENSES | C45: =SUM(C29,C35,C43) | D45: =SUM(D29,D35,D43) | E45: =SUM(E29,E35,E43) | F45: =SUM(F29,F35,F43) | G45: =SUM(G29,G35,G43) | H45: =IFERROR(G45/$G$9,0)
B47: OPERATING PROFIT / (LOSS) | C47: =C20-C45 | D47: =D20-D45 | E47: =E20-E45 | F47: =F20-F45 | G47: =SUM(C47:F47) | H47: =IFERROR(G47/$G$9,0)
B48: Net Margin % | C48: =IFERROR(C47/C9,0) | D48: =IFERROR(D47/D9,0) | E48: =IFERROR(E47/E9,0) | F48: =IFERROR(F47/F9,0) | G48: =IFERROR(G47/G9,0)
...

Sheet Monthly P&L
B1: Monthly P&L Detail | FY 2025-26 | Apr 2025 – Mar 2026 | Automated from Zoho + BigQuery
B3: Line Item | C3: Apr | D3: May | E3: Jun | F3: Jul | G3: Aug | H3: Sep | I3: Oct | J3: Nov | K3: Dec | L3: Jan | M3: Feb | N3: Mar
B4: REVENUE
B5: Tech Mahindra | C5: 100000 | D5: 0 | E5: 0 | F5: 0 | G5: 0 | H5: 0 | I5: 0 | J5: 0 | K5: 0 | L5: 0 | M5: 0 | N5: 0
B6: BSM Revenue | C6: 0 | D6: 50000 | E6: 0 | F6: 0 | G6: 0 | H6: 0 | I6: 0 | J6: 0 | K6: 0 | L6: 0 | M6: 0 | N6: 0
B7: FD Interest | C7: 5000 | D7: 0 | E7: 0 | F7: 0 | G7: 0 | H7: 0 | I7: 0 | J7: 0 | K7: 0 | L7: 0 | M7: 0 | N7: 0
B8: TOTAL REVENUE | C8: =SUM(C5:C7) | D8: =SUM(D5:D7) | E8: =SUM(E5:E7) | F8: =SUM(F5:F7) | G8: =SUM(G5:G7) | H8: =SUM(H5:H7) | I8: =SUM(I5:I7) | J8: =SUM(J5:J7) | ... N8: =SUM(N5:N7)
B9: COGS
B10: COGS Total | C10: ='COGS Allocation Working'!E15+25800.0 | D10: ='COGS Allocation Working'!F15+25800.0 | E10: ='COGS Allocation Working'!G15+25800.0 | F10: ='COGS Allocation Working'!H15+25800.0 | G10: ='COGS Allocation Working'!I15+25800.0 | H10: ='COGS Allocation Working'!J15+25800.0 | I10: ='COGS Allocation Working'!K15+25800.0 | J10: ='COGS Allocation Working'!L15+25800.0 | ... N10: ='COGS Allocation Working'!P15+25800.0
B11: GROSS PROFIT | C11: =C8-C10 | D11: =D8-D10 | E11: =E8-E10 | F11: =F8-F10 | G11: =G8-G10 | H11: =H8-H10 | I11: =I8-I10 | J11: =J8-J10 | ... N11: =N8-N10
B12: S&M
B13: Ramki S&M | C13: 1125000 | D13: 1125000 | E13: 1125000 | F13: 1125000 | G13: 1125000 | H13: 562500 | I13: 562500 | J13: 562500 | K13: 562500 | L13: 562500 | M13: 562500 | N13: 562500
B14: Advertising | C14: 0 | D14: 0 | E14: 0 | F14: 0 | G14: 0 | H14: 0 | I14: 0 | J14: 0 | K14: 0 | L14: 0 | M14: 0 | N14: 0
B15: Travel | C15: 0 | D15: 0 | E15: 0 | F15: 0 | G15: 0 | H15: 0 | I15: 0 | J15: 0 | K15: 0 | L15: 0 | M15: 0 | N15: 0
B16: Meals | C16: 0 | D16: 0 | E16: 0 | F16: 0 | G16: 0 | H16: 0 | I16: 0 | J16: 0 | K16: 0 | L16: 0 | M16: 0 | N16: 0
B17: S&M Total | C17: =SUM(C13:C16) | D17: =SUM(D13:D16) | E17: =SUM(E13:E16) | F17: =SUM(F13:F16) | G17: =SUM(G13:G16) | H17: =SUM(H13:H16) | I17: =SUM(I13:I16) | J17: =SUM(J13:J16) | ... N17: =SUM(N13:N16)
B18: R&D
B19: R&D Salaries | C19: 0 | D19: 0 | E19: 0 | F19: 0 | G19: 0 | H19: 0 | I19: 0 | J19: 0 | K19: 0 | L19: 0 | M19: 0 | N19: 0
B20: Consultant Exp. | C20: 0 | D20: 0 | E20: 0 | F20: 0 | G20: 0 | H20: 0 | I20: 0 | J20: 0 | K20: 0 | L20: 0 | M20: 0 | N20: 0
B21: Software Subs | C21: 0 | D21: 0 | E21: 0 | F21: 0 | G21: 0 | H21: 0 | I21: 0 | J21: 0 | K21: 0 | L21: 0 | M21: 0 | N21: 0
B22: R&D Total | C22: =SUM(C19:C21) | D22: =SUM(D19:D21) | E22: =SUM(E19:E21) | F22: =SUM(F19:F21) | G22: =SUM(G19:G21) | H22: =SUM(H19:H21) | I22: =SUM(I19:I21) | J22: =SUM(J19:J21) | ... N22: =SUM(N19:N21)
B23: G&A
B24: Rent | C24: 0 | D24: 20000 | E24: 0 | F24: 0 | G24: 0 | H24: 0 | I24: 0 | J24: 0 | K24: 0 | L24: 0 | M24: 0 | N24: 0
B25: IT & Internet | C25: 0 | D25: 0 | E25: 0 | F25: 0 | G25: 0 | H25: 0 | I25: 0 | J25: 0 | K25: 0 | L25: 0 | M25: 0 | N25: 0
B26: Legal | C26: 0 | D26: 0 | E26: 0 | F26: 0 | G26: 0 | H26: 0 | I26: 0 | J26: 0 | K26: 0 | L26: 0 | M26: 0 | N26: 0
B27: Audit & Non-Op | C27: 0 | D27: 0 | E27: 0 | F27: 0 | G27: 0 | H27: 0 | I27: 0 | J27: 0 | K27: 0 | L27: 0 | M27: 0 | N27: 0
B28: Other G&A | C28: 0 | D28: 0 | E28: 0 | F28: 0 | G28: 0 | H28: 0 | I28: 0 | J28: 0 | K28: 0 | L28: 0 | M28: 0 | N28: 0
B29: G&A Total | C29: =SUM(C24:C28) | D29: =SUM(D24:D28) | E29: =SUM(E24:E28) | F29: =SUM(F24:F28) | G29: =SUM(G24:G28) | H29: =SUM(H24:H28) | I29: =SUM(I24:I28) | J29: =SUM(J24:J28) | ... N29: =SUM(N24:N28)
B30: TOTAL OPEX | C30: =SUM(C17,C22,C29) | D30: =SUM(D17,D22,D29) | E30: =SUM(E17,E22,E29) | F30: =SUM(F17,F22,F29) | G30: =SUM(G17,G22,G29) | H30: =SUM(H17,H22,H29) | I30: =SUM(I17,I22,I29) | J30: =SUM(J17,J22,J29) | ... N30: =SUM(N17,N22,N29)
B31: NET PROFIT/(LOSS) | C31: =C11-C30 | D31: =D11-D30 | E31: =E11-E30 | F31: =F11-F30 | G31: =G11-G30 | H31: =H11-H30 | I31: =I11-I30 | J31: =J11-J30 | ... N31: =N11-N30

Sheet COGS Allocation Working
B1: COGS Allocation Detail | Delivery Staff + Vendors | TechM COGS from 2025-09 | BSM delivery from 2025-07
B3: Person / Vendor | C3: Allocation % | D3: Type | E3: Apr | F3: May | G3: Jun | H3: Jul | I3: Aug | J3: Sep | K3: Oct | L3: Nov | M3: Dec | N3: Jan | O3: Feb | P3: Mar | Q3: FY Total
B4: Parashar (CPO) | C4: 100% TechM (Sep-Mar) 25% BSM (Jul-Aug) | D4: FTE | E4: 0 | F4: 0 | G4: 0 | H4: 0 | I4: 0 | J4: 0 | K4: 0 | L4: 0 | M4: 0 | N4: 0 | O4: 0 | P4: 0 | Q4: =SUM(E4:P4)
B5: Sangeeth Nair | C5: 100% TechM (Sep-Mar) | D5: FTE | E5: 0 | F5: 0 | G5: 0 | H5: 0 | I5: 0 | J5: 0 | K5: 0 | L5: 0 | M5: 0 | N5: 0 | O5: 0 | P5: 0 | Q5: =SUM(E5:P5)
B6: Jitin Mangla | C6: 100% TechM (Sep-Mar) | D6: FTE | E6: 0 | F6: 0 | G6: 0 | H6: 0 | I6: 0 | J6: 0 | K6: 0 | L6: 0 | M6: 0 | N6: 0 | O6: 0 | P6: 0 | Q6: =SUM(E6:P6)
B7: Dipti Tiwari | C7: 100% TechM (Sep-Mar) | D7: FTE | E7: 0 | F7: 0 | G7: 0 | H7: 0 | I7: 0 | J7: 0 | K7: 0 | L7: 0 | M7: 0 | N7: 0 | O7: 0 | P7: 0 | Q7: =SUM(E7:P7)
B8: Dhanashri Saner | C8: 100% TechM (Sep-Mar) | D8: FTE | E8: 0 | F8: 0 | G8: 0 | H8: 0 | I8: 0 | J8: 0 | K8: 0 | L8: 0 | M8: 0 | N8: 0 | O8: 0 | P8: 0 | Q8: =SUM(E8:P8)
B9: Pinkesh Sethiya | C9: 100% TechM (Jan-Mar) | D9: FTE | E9: 0 | F9: 0 | G9: 0 | H9: 0 | I9: 0 | J9: 0 | K9: 0 | L9: 0 | M9: 0 | N9: 0 | O9: 0 | P9: 0 | Q9: =SUM(E9:P9)
B10: Ramki (CEO-US) | C10: 50% COGS (Sep-Mar) | D10: Consultant | E10: 0 | F10: 0 | G10: 0 | H10: 0 | I10: 0 | J10: 562500 | K10: 562500 | L10: 562500 | M10: 562500 | N10: 562500 | O10: 562500 | P10: 562500 | Q10: =SUM(E10:P10)
B11: Dorothea Stoll | C11: 100% COGS (Oct-Mar) | D11: Consultant | E11: 0 | F11: 0 | G11: 0 | H11: 0 | I11: 0 | J11: 0 | K11: 0 | L11: 0 | M11: 0 | N11: 0 | O11: 0 | P11: 0 | Q11: =SUM(E11:P11)
B12: BSM Crew (Kashish+ Priyanka+Nitin) | C12: 100% BSM (Jul-Sep) | D12: Contractor | E12: 0 | F12: 0 | G12: 0 | H12: 0 | I12: 0 | J12: 0 | K12: 0 | L12: 0 | M12: 0 | N12: 0 | O12: 0 | P12: 0 | Q12: =SUM(E12:P12)
B13: Conam Tech | C13: 100% COGS (Aug-Oct) | D13: Vendor | E13: 40000 | F13: 0 | G13: 0 | H13: 0 | I13: 0 | J13: 0 | K13: 0 | L13: 0 | M13: 0 | N13: 0 | O13: 0 | P13: 0 | Q13: =SUM(E13:P13)
B14: Biltzentech | C14: 100% COGS (Nov-Mar) | D14: Vendor | E14: 0 | F14: 0 | G14: 0 | H14: 0 | I14: 0 | J14: 0 | K14: 0 | L14: 0 | M14: 0 | N14: 0 | O14: 0 | P14: 0 | Q14: =SUM(E14:P14)
B15: TOTAL COGS | E15: =SUM(E4:E14) | F15: =SUM(F4:F14) | G15: =SUM(G4:G14) | H15: =SUM(H4:H14) | I15: =SUM(I4:I14) | J15: =SUM(J4:J14) | K15: =SUM(K4:K14) | L15: =SUM(L4:L14) | ... P15: =SUM(P4:P14) | Q15: =SUM(E15:P15)
B17: Allocation Notes: BSM delivery = Kashish (100% Jul-Sep) + Priyanka (100%) + Nitin Chandani (100%) + Parashar (25% Jul-Aug). TechM delivery = all FTE staff except Pareek (R&D/G&A) and Yash (R&D). Megha (R&D). Pinkesh joins Jan 2026 → TechM. Ramki 100% S&M Apr-Aug; 50%/50% S&M/COGS Sep-Mar. Dorothea: 100% COGS as account + delivery manager.
